
### Exceptions

- await throws if there are exceptions
- it will thow the first exception, if there are more
- cancellations are also exceptions (OperationCancelled and TaskCancelled)
- task.Wait()/task.Result wraps all exceptions into an AggregatedException
- task.GetAwaiter().GetResult() does not wrap exceptions
- task.Exception does not throw. It's null if not faulted otherwise it's the exception.
- async void methods exceptions are re-thrown if there is a SynchronizationContext (UI)
- TaskScheduler.UnobservedTaskException [https://msdn.microsoft.com/en-us/library/system.threading.tasks.taskscheduler.unobservedtaskexception.aspx](https://msdn.microsoft.com/en-us/library/system.threading.tasks.taskscheduler.unobservedtaskexception.aspx)
